Workbook

Sheet Summary
A2: Multi-role e-commerce system (Buyer, Seller, Logistics, Rider)
A4: Test run details
A5: System under test
A6: Version / build
A7: Test environment (browser, device)
A8: Tester
A9: Date tested
A11: Results by role
A12: Role (sheet) | B12: Total test cases | C12: Pass | D12: Fail | E12: Blocked | F12: Not Run | G12: Pass rate (Pass / Total)
A13: Buyer | B13: =COUNTA(Buyer!$A$2:$A$200) -> 30 | C13: =COUNTIF(Buyer!$L$2:$L$200,"Pass") -> 0 | D13: =COUNTIF(Buyer!$L$2:$L$200,"Fail") -> 0 | E13: =COUNTIF(Buyer!$L$2:$L$200,"Blocked") -> 0 | F13: =COUNTIF(Buyer!$L$2:$L$200,"Not Run") -> 0 | G13: =IF(B13=0,0,C13/B13) -> 0
A14: Seller | B14: =COUNTA(Seller!$A$2:$A$200) -> 44 | C14: =COUNTIF(Seller!$L$2:$L$200,"Pass") -> 0 | D14: =COUNTIF(Seller!$L$2:$L$200,"Fail") -> 0 | E14: =COUNTIF(Seller!$L$2:$L$200,"Blocked") -> 0 | F14: =COUNTIF(Seller!$L$2:$L$200,"Not Run") -> 7 | G14: =IF(B14=0,0,C14/B14) -> 0
A15: Logistics | B15: =COUNTA(Logistics!$A$2:$A$200) -> 44 | C15: =COUNTIF(Logistics!$L$2:$L$200,"Pass") -> 0 | D15: =COUNTIF(Logistics!$L$2:$L$200,"Fail") -> 0 | E15: =COUNTIF(Logistics!$L$2:$L$200,"Blocked") -> 0 | F15: =COUNTIF(Logistics!$L$2:$L$200,"Not Run") -> 2 | G15: =IF(B15=0,0,C15/B15) -> 0
A16: Rider | B16: =COUNTA(Rider!$A$2:$A$200) -> 32 | C16: =COUNTIF(Rider!$L$2:$L$200,"Pass") -> 0 | D16: =COUNTIF(Rider!$L$2:$L$200,"Fail") -> 0 | E16: =COUNTIF(Rider!$L$2:$L$200,"Blocked") -> 0 | F16: =COUNTIF(Rider!$L$2:$L$200,"Not Run") -> 32 | G16: =IF(B16=0,0,C16/B16) -> 0
A17: Total | B17: =SUM(B13:B16) -> 150 | C17: =SUM(C13:C16) -> 0 | D17: =SUM(D13:D16) -> 0 | E17: =SUM(E13:E16) -> 0 | F17: =SUM(F13:F16) -> 41 | G17: =IF(B17=0,0,C17/B17) -> 0
A19: How to use this workbook
A20: 1. Read the Assumptions sheet first. The rules are modeled on Philippine marketplaces, so adjust any case whose rule differs from your system.
A21: 2. The Test Data sheet lists every form field with two ready-made accounts per role. The Test Files sheet lists the upload files to prepare. All people, companies and numbers are fictional.
A22: 3. Emails use example.com, so nothing is delivered to a real inbox. Read OTP and activation emails from a mail catcher such as Mailtrap, or from your application's mail log.
A23: 4. On each role sheet, run the Test Steps with the Test Data and compare what happens with the Expected Result. Use a spare email and mobile number from the Test Data sheet whenever a value marked (accept) creates another account.
A24: 5. Dates of birth and license expiry dates in the boundary cases are calculated from today's date, so they are always correct on the day you test.
A25: 6. Fill in only the yellow cells: Actual Result, Status and Remarks. Pick the Status from the dropdown (Pass, Fail, Blocked, Not Run).
A26: 7. Pass = actual matches expected. Fail = it does not (describe what happened and add a screenshot or bug number in Remarks). Blocked = the case could not be run, for example because an earlier case failed.
A27: 8. The Results by role table above updates automatically from the Status column.
A29: Example of a filled-in row (illustration only, not a real result)
A30: Test Case ID | B30: Test Scenario | C30: Expected Result | D30: Actual Result | E30: Status | F30: Remarks
A31: TC-BUY-010 | B31: Email that is already registered | C31: Registration is blocked. A message says the email is already in use. No account is created. | D31: No message was shown. A second account was created with juanmiguel.delacruz@example.com. | E31: Fail | F31: Bug #012. Screenshot: buy-010.png
A34: Black-box techniques used
A35: Equivalence Partitioning | B35: Inputs are grouped into valid and invalid classes, and one value from each class is tested.
A36: Boundary Value Analysis | B36: Values at and just beyond a limit are tested, for example 7 and 8 characters for a minimum of 8.
A37: Decision Table | B37: Combinations of conditions are tested, for example each missing password character type.
A38: State Transition | B38: Changes in account status are tested, for example Unverified to Active or Pending Approval to Approved.
A39: Use Case Testing | B39: A complete user flow is tested from start to finish with valid data.
A40: Error Guessing | B40: Likely mistakes are tested based on experience, for example double-clicking Register or pasting another role's URL.

Sheet Test Data
A1: Test data and input details
A2: Every form field per role, with its rule and two complete sets of valid data. Account 1 is the main account in the test cases. Account 2 is for cases that need a second account. All people, companies, numbers and addresses are fictional.
A4: Buyer: Self-registration
A5: Role | B5: Field | C5: Required | D5: Input type | E5: Format / rule | F5: Account 1 (valid) | G5: Account 2 (valid)
A6: Buyer | B6: First Name | C6: Yes | D6: Text | E6: 2 to 50 characters; letters, spaces, hyphen, apostrophe, period | F6: Juan Miguel | G6: Ana Marie
A7: Buyer | B7: Last Name | C7: Yes | D7: Text | E7: 2 to 50 characters; letters, spaces, hyphen, apostrophe, period | F7: Dela Cruz | G7: Reyes
A8: Buyer | B8: Email | C8: Yes | D8: Email | E8: Valid email format; unique | F8: juanmiguel.delacruz@example.com | G8: anamarie.reyes@example.com
A9: Buyer | B9: Mobile Number | C9: Yes | D9: Text | E9: 09XXXXXXXXX or +639XXXXXXXXX; unique | F9: 09171234567 | G9: 09173456789
A10: Buyer | B10: Date of Birth | C10: Yes | D10: Date picker | E10: At least 18 years old | F10: 05/14/1998 | G10: 11/02/2001
A11: Buyer | B11: Password | C11: Yes | D11: Password | E11: Min 8 characters; uppercase, lowercase, number, special character | F11: Mamimili@2026 | G11: Suki#2026Ana
A12: Buyer | B12: Confirm Password | C12: Yes | D12: Password | E12: Must match Password | F12: Mamimili@2026 | G12: Suki#2026Ana
A13: Buyer | B13: Terms and Privacy Policy | C13: Yes | D13: Checkbox | E13: Must be ticked | F13: Ticked | G13: Ticked
A15: Seller: Self-registration, then admin approval
A16: Role | B16: Field | C16: Required | D16: Input type | E16: Format / rule | F16: Account 1 (valid) | G16: Account 2 (valid)
A17: Seller | B17: First Name | C17: Yes | D17: Text | E17: 2 to 50 characters; letters, spaces, hyphen, apostrophe, period | F17: Maria Clara | G17: Roberto
A18: Seller | B18: Last Name | C18: Yes | D18: Text | E18: 2 to 50 characters; letters, spaces, hyphen, apostrophe, period | F18: Santos | G18: Villanueva
A19: Seller | B19: Email | C19: Yes | D19: Email | E19: Valid email format; unique | F19: mariaclara.santos@example.com | G19: roberto.villanueva@example.com
A20: Seller | B20: Mobile Number | C20: Yes | D20: Text | E20: 09XXXXXXXXX or +639XXXXXXXXX; unique | F20: 09189876543 | G20: 09194567890
A21: Seller | B21: Shop Name | C21: Yes | D21: Text | E21: 3 to 30 characters; unique | F21: Maria Clara Handicrafts | G21: RV Gadget Hub
A22: Seller | B22: Shop Category | C22: Yes | D22: Dropdown | E22: One main category | F22: Home & Living | G22: Mobiles & Gadgets
A23: Seller | B23: Seller Type | C23: Yes | D23: Dropdown | E23: Individual, Sole Proprietorship or Corporation | F23: Sole Proprietorship | G23: Corporation
A24: Seller | B24: TIN | C24: Yes | D24: Text | E24: 000-000-000-000 (12 digits); unique | F24: 123-456-789-000 | G24: 456-789-012-000
A25: Seller | B25: Region | C25: Yes | D25: Dropdown | E25: Philippine regions | F25: National Capital Region (NCR) | G25: Region VII (Central Visayas)
A26: Seller | B26: Province | C26: Yes | D26: Dropdown | E26: Filtered by Region | F26: Metro Manila | G26: Cebu
A27: Seller | B27: City / Municipality | C27: Yes | D27: Dropdown | E27: Filtered by Province | F27: Quezon City | G27: Cebu City
... A37: Seller | B37: Terms and Privacy Policy | C37: Yes | D37: Checkbox | E37: Must be ticked | F37: Ticked | G37: Ticked
A39: Logistics: Self-registration, then admin approval
A40: Role | B40: Field | C40: Required | D40: Input type | E40: Format / rule | F40: Account 1 (valid) | G40: Account 2 (valid)
A41: Logistics | B41: Company Name | C41: Yes | D41: Text | E41: Unique | F41: Bilis Hatid Express Inc. | G41: Agila Cargo Movers Corp.
A42: Logistics | B42: SEC Registration No. | C42: Yes | D42: Text | E42: 2 letters followed by 9 digits; unique | F42: CS202012345 | G42: CS201998765
A43: Logistics | B43: TIN | C43: Yes | D43: Text | E43: 000-000-000-000 (12 digits); unique | F43: 234-567-890-000 | G43: 567-890-123-000
A44: Logistics | B44: Region | C44: Yes | D44: Dropdown | E44: Philippine regions | F44: National Capital Region (NCR) | G44: Region XI (Davao Region)
A45: Logistics | B45: Province | C45: Yes | D45: Dropdown | E45: Filtered by Region | F45: Metro Manila | G45: Davao del Sur
A46: Logistics | B46: City / Municipality | C46: Yes | D46: Dropdown | E46: Filtered by Province | F46: Pasig City | G46: Davao City
A47: Logistics | B47: Barangay | C47: Yes | D47: Dropdown | E47: Filtered by City / Municipality | F47: Kapitolyo | G47: Buhangin
A48: Logistics | B48: Street Address | C48: Yes | D48: Text | E48: House, unit or lot number and street | F48: Unit 5B, 88 West Capitol Drive | G48: Door 3, 210 Sampaguita St.
A49: Logistics | B49: Postal Code | C49: Yes | D49: Text | E49: Exactly 4 digits | F49: 1603 | G49: 8000
A50: Logistics | B50: Contact Person First Name | C50: Yes | D50: Text | E50: 2 to 50 characters; letters, spaces, hyphen, apostrophe, period | F50: Carlos Antonio | G50: Liza Mae
A51: Logistics | B51: Contact Person Last Name | C51: Yes | D51: Text | E51: 2 to 50 characters; letters, spaces, hyphen, apostrophe, period | F51: Mendoza | G51: Fernandez
... A62: Logistics | B62: Terms and Privacy Policy | C62: Yes | D62: Checkbox | E62: Must be ticked | F62: Ticked | G62: Ticked
...

Sheet Test Files
A1: Upload files to prepare
A2: Prepare these files before testing the document uploads. Use sample or blank documents, not anyone's real ID or certificate. The size limit is 5 MB, which is 5,120 KB or 5,242,880 bytes.
A4: File name | B4: Type | C4: Size | D4: Used for | E4: Expected result
A5: govt_id_front.jpg | B5: JPG | C5: 1.2 MB | D5: Valid government ID | E5: Accept
A6: govt_id_front.png | B6: PNG | C6: 2.4 MB | D6: Valid government ID in PNG | E6: Accept
A7: dti_certificate.pdf | B7: PDF | C7: 850 KB | D7: DTI Certificate of Business Name Registration | E7: Accept
A8: dti_certificate_clear.pdf | B8: PDF | C8: 1.0 MB | D8: Replacement document for the resubmit test (seller) | E8: Accept
A9: sec_certificate.pdf | B9: PDF | C9: 1.0 MB | D9: SEC Certificate of Registration | E9: Accept
A10: bir_2303.pdf | B10: PDF | C10: 1.1 MB | D10: BIR Certificate of Registration (Form 2303) | E10: Accept
A11: mayors_permit.pdf | B11: PDF | C11: 1.3 MB | D11: Mayor's / Business Permit | E11: Accept
A12: mayors_permit_2026.pdf | B12: PDF | C12: 1.2 MB | D12: Replacement document for the resubmit test (logistics) | E12: Accept
A13: drivers_license.jpg | B13: JPG | C13: 1.5 MB | D13: Rider's driver's license | E13: Accept
A14: drivers_license.png | B14: PNG | C14: 2.0 MB | D14: Rider's driver's license in PNG | E14: Accept
A15: drivers_license.pdf | B15: PDF | C15: 700 KB | D15: Rider's driver's license in PDF | E15: Accept
... A22: installer.exe | B22: EXE | C22: 2.1 MB | D22: Wrong file type (program) | E22: Reject

Sheet Assumptions
A1: Assumptions used in the test cases
A2: These rules are modeled on Philippine marketplaces, not taken from your actual system. Write your real rule in column D where it differs, then filter the Assumption Ref column on each role sheet to find the test cases to adjust.
A4: Ref | B4: Topic | C4: Assumed rule | D4: Your system's actual rule (fill in if different)
A5: A1 | B5: Form fields | C5: Each role's form has the fields listed on the Test Data sheet, modeled on Philippine marketplaces. Payout details (bank or e-wallet) are set up after approval, not during registration.
A6: A2 | B6: Name rule | C6: 2 to 50 characters. Letters (including ñ), spaces, hyphen, apostrophe and period only.
A7: A3 | B7: Email rule | C7: Must be a valid email format. Unique across all roles (one email = one account). Not case-sensitive. Leading and trailing spaces are removed.
A8: A4 | B8: Mobile number rule | C8: Philippine mobile number entered as 09XXXXXXXXX (11 digits) or +639XXXXXXXXX. Both forms are stored as the same number. Unique across all accounts.
A9: A5 | B9: Password rule | C9: At least 8 characters with at least one uppercase letter, one lowercase letter, one number and one special character. Confirm Password must match.
A10: A6 | B10: Date of birth rule | C10: Buyers and riders must be at least 18 years old on the day of registration. A future date is not allowed.
A11: A7 | B11: Address rule | C11: Region, Province, City/Municipality and Barangay are linked dropdowns: each list depends on the one before it. Postal Code is exactly 4 digits.
A12: A8 | B12: TIN rule | C12: 12 digits in the form 000-000-000-000 (9-digit TIN plus 3-digit branch code). Unique across seller and logistics accounts.
A13: A9 | B13: Email verification (OTP) | C13: A 6-digit numeric code is emailed after registration. It is valid for 5 minutes. Resending creates a new code and cancels the old one. An account cannot be used until it is verified.
A14: A10 | B14: Document upload rule | C14: Accepted file types: JPG, PNG, PDF. Maximum size: 5 MB (5,120 KB) per file.
A15: A11 | B15: Seller documents by seller type | C15: Individual: Government-issued ID. Sole Proprietorship: Government-issued ID, DTI Certificate and BIR Form 2303. Corporation: Government-issued ID of the representative, SEC Certificate and BIR Form 2303.
A16: A12 | B16: Account status flow | C16: Buyer: Unverified, then Active after OTP. Seller and Logistics: Unverified, then Pending Approval after OTP, then Approved or Rejected by an admin. A rejected applicant can correct the details and resubmit.
... A20: A16 | B20: Role-based access | C20: Each role can open only its own pages. Opening another role's page is denied (error 403 or redirect).

Sheet Buyer
A1: Test Case ID | B1: Module | C1: Test Scenario | D1: Technique | E1: Priority | F1: Preconditions | G1: Test Steps | H1: Test Data | I1: Expected Result | J1: Assumption Ref | K1: Actual Result | L1: Status | M1: Remarks
A2: TC-BUY-001 | B2: Registration Form | C2: Register with all valid data | D2: Use Case Testing | E2: High | F2: The buyer registration page is open. The email, mobile number and other unique values in the test data are not yet registered. | G2: 1. Fill in every field with the test data. 2. Click Register. | H2: First Name: Juan Miguel Last Name: Dela Cruz Email: juanmiguel.delacruz@example.com Mobile Number: 09171234567 Date of Birth: 05/14/1998 Password: Mamimili@2026 Confirm Password: Mamimili@2026 Terms and Privacy Policy: Ticked | I2: The form is accepted with no validation errors. A success message is shown, a 6-digit OTP is sent to the email, and the email verification page opens. The account is saved with status Unverified. | J2: A1, A9, A12 | K2: everything is functional and working | L2: Run | M2: PASSED
A3: TC-BUY-002 | B3: Required Fields | C3: Submit a completely empty form | D3: Equivalence Partitioning | E3: High | F3: The buyer registration page is open. | G3: 1. Leave every field blank and every dropdown on its default option. 2. Click Register. | H3: All fields blank | I3: Registration is blocked. A required-field message is shown for every mandatory field. No account is created and no OTP is sent. | J3: A1 | K3: Completely Blank registration gets blocked | L3: Run | M3: PASSED
A4: TC-BUY-003 | B4: Required Fields | C4: Leave one required field blank at a time | D4: Equivalence Partitioning | E4: High | F4: The buyer registration page is open. | G4: 1. Fill in all fields with valid data. 2. Clear one required field. 3. Click Register. 4. Repeat for each field in the test data. | H4: Clear in turn: First Name Last Name Email Mobile Number Date of Birth Password Confirm Password | I4: Each time, registration is blocked and a required-field message is shown on the blank field only. Other entered values (except passwords and uploads) are kept. No account is created. | J4: A1 | K4: Registration required field message gets shown on every missing field | L4: Run | M4: PASSED
A5: TC-BUY-004 | B5: Name | C5: Name with numbers or symbols | D5: Equivalence Partitioning | E5: Medium | F5: The buyer registration page is open. | G5: 1. Fill in all other fields with valid data. 2. Enter the test data in the name fields. 3. Click Register. | H5: First Name: Juan Miguel123 Last Name: Dela Cruz@# | I5: Registration is blocked. A message on each name field says only letters are allowed. | J5: A2 | K5: Inputting numbers on name fields gets blocked | L5: Run | M5: PASSED
A6: TC-BUY-005 | B6: Name | C6: Name with ñ and allowed punctuation | D6: Equivalence Partitioning | E6: Low | F6: The buyer registration page is open. The email, mobile number and other unique values in the test data are not yet registered. | G6: 1. Fill in all other fields with valid data. 2. Enter the test data in the name fields. 3. Click Register. | H6: First Name: Niño Angelo Last Name: Peñaflor-O'Hara | I6: The names are accepted and saved exactly as typed, including ñ. | J6: A2 | K6: Name with ñ gets accepted | L6: Run | M6: PASSED
A7: TC-BUY-006 | B7: Name | C7: Name length at the limits | D7: Boundary Value Analysis | E7: Medium | F7: The buyer registration page is open. The email, mobile number and other unique values in the test data are not yet registered. | G7: 1. Fill in all other fields with valid data. 2. Enter each first name in the test data, one per attempt. 3. Click Register. | H7: 1 character: J (reject) 2 characters: Jo (accept) 50 characters: Maria Cristina Angelica Bernadette Josefina Leonor (accept) 51 characters: Maria Cristina Angelica Bernadette Josefina Leonora (reject) | I7: 1 and 51 characters are rejected with a length message. 2 and 50 characters are accepted. | J7: A2 | K7: 1 - 51 length names and characters still gets accepted | L7: Run | M7: FAILED
A8: TC-BUY-007 | B8: Date of Birth | C8: Age at the 18-year limit | D8: Boundary Value Analysis | E8: High | F8: The buyer registration page is open. The email, mobile number and other unique values in the test data are not yet registered. | G8: 1. Fill in all other fields with valid data. 2. Enter each date of birth in the test data, one per attempt. 3. Click Register. | H8: ="Born "&TEXT(EDATE(TODAY(),-216)+1,"mm/dd/yyyy")&" (17 years old, reject)"&CHAR(10)&"Born "&TEXT(EDATE(TODAY(),-216),"mm/dd/yyyy")&" (turns 18 today, accept)"&CHAR(10)&"Born "&TEXT(EDATE(TODAY(),-216)-1,"mm/dd/yyyy")&" (18 years and 1 day, accept)" -> Born 10/15/2008 (17 years old, reject) Born 10/14/2008 (turns 18 today, accept) Born 10/13/2008 (18 years and 1 day, accept) | I8: The 17-year-old date is rejected with a message that the person must be at least 18. The other two dates are accepted. | J8: A6 | K8: Minors are rejected. | L8: Run | M8: PASSED
A9: TC-BUY-008 | B9: Date of Birth | C9: Date of birth in the future | D9: Equivalence Partitioning | E9: Medium | F9: The buyer registration page is open. | G9: 1. Fill in all other fields with valid data. 2. Enter the date of birth in the test data. 3. Click Register. | H9: ="Date of Birth: "&TEXT(TODAY()+1,"mm/dd/yyyy")&" (tomorrow)" -> Date of Birth: 10/15/2026 (tomorrow) | I9: Registration is blocked. A message asks for a valid date of birth. If a date picker is used, future dates cannot be selected. | J9: A6 | K9: Registration is blocked. | L9: Run | M9: PASSED
A10: TC-BUY-009 | B10: Email | C10: Email in an invalid format | D10: Equivalence Partitioning | E10: High | F10: The buyer registration page is open. | G10: 1. Fill in all other fields with valid data. 2. Enter each email in the test data, one per attempt. 3. Click Register. | H10: juanmiguel.delacruzexample.com (no @) juanmiguel.delacruz@ (no domain) @example.com (no name) juanmiguel.delacruz@example (no .com) juanmiguel delacruz@example.com (space) | I10: Each value is rejected with a message asking for a valid email address. No account is created. | J10: A3 | K10: Invalid email address prompts a message that the email is missing @ preventing the account from being created | L10: Run | M10: PASSED
A11: TC-BUY-010 | B11: Email | C11: Email that is already registered | D11: Equivalence Partitioning | E11: High | F11: The buyer registration page is open. The buyer account juanmiguel.delacruz@example.com already exists. | G11: 1. Fill in all other fields with valid data. 2. Enter the existing email. 3. Click Register. | H11: Email: juanmiguel.delacruz@example.com | I11: Registration is blocked. A message says the email is already in use. No account is created. | J11: A3 | K11: When creating an account with a already registered email the registration gets blocked | L11: Run | M11: PASSED
A12: TC-BUY-011 | B12: Email | C12: Registered email typed in capital letters | D12: Error Guessing | E12: Medium | F12: The buyer registration page is open. The buyer account juanmiguel.delacruz@example.com already exists. | G12: 1. Fill in all other fields with valid data. 2. Enter the same email in capital letters. 3. Click Register. | H12: Email: JUANMIGUEL.DELACRUZ@EXAMPLE.COM | I12: The email is treated as a duplicate. Registration is blocked. | J12: A3 | K12: Email address inputted with capital letters treats the email as a duplicate from a normal email address | L12: Run | M12: PASSED
A13: TC-BUY-012 | B13: Email | C13: Email with spaces before and after | D13: Error Guessing | E13: Low | F13: The buyer registration page is open. The email, mobile number and other unique values in the test data are not yet registered. | G13: 1. Fill in all other fields with valid data. 2. Type two spaces before and after the email. 3. Click Register. | H13: Email: " buyer.test01@example.com " | I13: The spaces are removed and the email is saved as buyer.test01@example.com. | J13: A3 | K13: Email address with space before it still saves the email without space | L13: Run | M13: PASSED
A14: TC-BUY-013 | B14: Mobile Number | C14: Mobile number in an invalid format | D14: Equivalence Partitioning | E14: High | F14: The buyer registration page is open. | G14: 1. Fill in all other fields with valid data. 2. Enter each mobile number in the test data, one per attempt. 3. Click Register. | H14: 0917ABC4567 (letters) 0917-123-456 (symbols, too short) 12345678901 (does not start with 09) 02-8123-4567 (landline) | I14: Each value is rejected with a message asking for a valid mobile number. | J14: A4 | K14: Invalid symbols and letters is prevented from being inputted | L14: Run | M14: PASSED
A15: TC-BUY-014 | B15: Mobile Number | C15: Mobile number length at the limits | D15: Boundary Value Analysis | E15: High | F15: The buyer registration page is open. The email, mobile number and other unique values in the test data are not yet registered. | G15: 1. Fill in all other fields with valid data. 2. Enter each mobile number in the test data, one per attempt. 3. Click Register. | H15: 10 digits: 0917123456 (reject) 11 digits: 09170000001 (accept) 12 digits: 091712345678 (reject) | I15: 10 and 12 digits are rejected with a length message. 11 digits is accepted. | J15: A4 | K15: Mobile number exceeding 11 digits prevents additional numbers from being inputted | L15: Run | M15: PASSED
A16: TC-BUY-015 | B16: Mobile Number | C16: Mobile number that is already registered | D16: Equivalence Partitioning | E16: Medium | F16: The buyer registration page is open. An account already exists with mobile number 09171234567. | G16: 1. Fill in all other fields with valid data. 2. Enter the existing mobile number. 3. Click Register. | H16: Mobile: 09171234567 | I16: Registration is blocked. A message says the mobile number is already in use. | J16: A4 | K16: Mobile number not yet included. | L16: Run | M16: FAILED
A17: TC-BUY-016 | B17: Mobile Number | C17: Registered number entered in +63 format | D17: Error Guessing | E17: Medium | F17: The buyer registration page is open. An account already exists with mobile number 09171234567. | G17: 1. Fill in all other fields with valid data. 2. Enter the same number in +63 format. 3. Click Register. | H17: Mobile: +639171234567 | I17: The +63 format is recognised as the same number. Registration is blocked. A message says the mobile number is already in use. | J17: A4 | K17: Doesn't accept + sign | L17: Run | M17: FAILED
A18: TC-BUY-017 | B18: Password | C18: Password length at the limit | D18: Boundary Value Analysis | E18: High | F18: The buyer registration page is open. The email, mobile number and other unique values in the test data are not yet registered. | G18: 1. Fill in all other fields with valid data. 2. Enter each password in both password fields, one per attempt. 3. Click Register. | H18: 7 characters: Bili@26 (reject) 8 characters: Bili@202 (accept) | I18: 7 characters is rejected with a minimum-length message. 8 characters is accepted. | J18: A5 | K18: It accepted 8 characters so its good | L18: Run | M18: PASSED
A19: TC-BUY-018 | B19: Password | C19: Password missing a required character type | D19: Decision Table | E19: High | F19: The buyer registration page is open. | G19: 1. Fill in all other fields with valid data. 2. Enter each password in both password fields, one per attempt. 3. Click Register. | H19: No uppercase: mamimili@2026 No lowercase: MAMIMILI@2026 No number: Mamimili@abcd No special character: Mamimili2026 | I19: Each password is rejected with a message stating the password rule. No account is created. | J19: A5 | K19: Accepted no number password | L19: Run | M19: FAILED
A20: TC-BUY-019 | B20: Password | C20: Confirm Password does not match | D20: Equivalence Partitioning | E20: High | F20: The buyer registration page is open. | G20: 1. Fill in all other fields with valid data. 2. Enter the test data in Password and Confirm Password. 3. Click Register. | H20: Password: Mamimili@2026 Confirm Password: Mamimili@2027 | I20: Registration is blocked. A message says the passwords do not match. | J20: A5 | K20: Doesn’t accept mismatch password | L20: Run | M20: PASSED
A21: TC-BUY-020 | B21: Password | C21: Password is hidden while typing | D21: Error Guessing | E21: Low | F21: The buyer registration page is open. | G21: 1. Type the password. 2. If a show/hide icon is provided, click it twice. | H21: Password: Mamimili@2026 | I21: Characters are hidden as dots by default. The icon reveals the password, then hides it again. | J21: A5 | K21: The symbol works when hiding and showing | L21: Run | M21: PASSED
... A31: TC-BUY-030 | B31: Access Control | C31: Open another role's pages | D31: Error Guessing | E31: High | F31: The buyer account juanmiguel.delacruz@example.com is logged in. | G31: 1. Paste the address of each dashboard in the test data into the browser, one at a time. | H31: Seller dashboard Logistics dashboard Rider dashboard Admin dashboard | I31: Access is denied each time (error 403 or redirect). No data from the other role is shown. | J31: A16 | K31: Access is denied. Error 403 | L31: Run | M31: PASSED

Sheet Seller
A1: Test Case ID | B1: Module | C1: Test Scenario | D1: Technique | E1: Priority | F1: Preconditions | G1: Test Steps | H1: Test Data | I1: Expected Result | J1: Assumption Ref | K1: Actual Result | L1: Status | M1: Remarks
A2: TC-SEL-001 | B2: Registration Form | C2: Register with all valid data | D2: Use Case Testing | E2: High | F2: The seller registration page is open. The email, mobile number and other unique values in the test data are not yet registered. | G2: 1. Fill in every field with the test data. 2. Click Register. | H2: First Name: Maria Clara Last Name: Santos Email: mariaclara.santos@example.com Mobile Number: 09189876543 Shop Name: Maria Clara Handicrafts Shop Category: Home & Living Seller Type: Sole Proprietorship TIN: 123-456-789-000 Region: National Capital Region (NCR) Province: Metro Manila City / Municipality: Quezon City Barangay: Commonwealth Street Address: Blk 12 Lot 8, Sampaguita St. Postal Code: 1121 Government-issued ID (upload): govt_id_front.jpg (1.2 MB) DTI Certificate (upload): dti_certificate.pdf (850 KB) BIR Form 2303 (upload): bir_2303.pdf (1.1 MB) Password: Tindahan@2026 Confirm Password: Tindahan@2026 Terms and Privacy Policy: Ticked | I2: The form is accepted with no validation errors. A success message is shown, a 6-digit OTP is sent to the email, and the email verification page opens. The account is saved with status Unverified. | J2: A1, A9, A12 | K2: I got through the first step and verified the email with the code, but I couldn't finish the seller profile. Metro Manila isn't in the province list, so I couldn't pick Quezon City. Home & Living isn't a category either, and most categories get rejected when you submit. I tried again with a Cebu address and Pet Supplies, but the page just showed a system error and nothing was saved. | L2: Run | M2: FAILED
A3: TC-SEL-002 | B3: Required Fields | C3: Submit a completely empty form | D3: Equivalence Partitioning | E3: High | F3: The seller registration page is open. | G3: 1. Leave every field blank and every dropdown on its default option. 2. Click Register. | H3: All fields blank | I3: Registration is blocked. A required-field message is shown for every mandatory field. No account is created and no OTP is sent. | J3: A1 | K3: The form wouldn't submit. Every required field was highlighted and asked to be filled in, on both the first step and the profile page. No account was created. | L3: Run | M3: PASSED
A4: TC-SEL-003 | B4: Required Fields | C4: Leave one required field blank at a time | D4: Equivalence Partitioning | E4: High | F4: The seller registration page is open. | G4: 1. Fill in all fields with valid data. 2. Clear one required field. 3. Click Register. 4. Repeat for each field in the test data. | H4: Clear in turn: First Name Last Name Email Mobile Number Shop Name Shop Category Seller Type TIN Region Province City / Municipality Barangay Street Address Postal Code Government-issued ID (upload) DTI Certificate (upload) BIR Form 2303 (upload) Password Confirm Password | I4: Each time, registration is blocked and a required-field message is shown on the blank field only. Other entered values (except passwords and uploads) are kept. No account is created. | J4: A1 | K4: Most fields showed a required message when I left them blank, and the rest of what I typed stayed in the form. But when Business Name or Business Permit was empty, I got a system error instead of a proper message. Also, every time the form came back with an error, I had to pick the province, city and barangay again. | L4: Run | M4: FAILED
A5: TC-SEL-004 | B5: Name | C5: Name with numbers or symbols | D5: Equivalence Partitioning | E5: Medium | F5: The seller registration page is open. | G5: 1. Fill in all other fields with valid data. 2. Enter the test data in the name fields. 3. Click Register. | H5: First Name: Maria Clara99 Last Name: Dela Cruz@# | I5: Registration is blocked. A message on each name field says only letters are allowed. | J5: A2 | K5: The page wouldn't let me type numbers or symbols in the name fields; they were removed as I typed. When I forced them through, the site rejected both names as an invalid format. | L5: Run | M5: PASSED
A6: TC-SEL-005 | B6: Name | C6: Name with ñ and allowed punctuation | D6: Equivalence Partitioning | E6: Low | F6: The seller registration page is open. The email, mobile number and other unique values in the test data are not yet registered. | G6: 1. Fill in all other fields with valid data. 2. Enter the test data in the name fields. 3. Click Register. | H6: First Name: Niña Corazon Last Name: Peñaranda-D'Souza | I6: The names are accepted and saved exactly as typed, including ñ. | J6: A2 | K6: The ñ disappears as soon as you type it, so Niña turned into Nia. Even when I got the ñ through, the site said the names were in an invalid format. | L6: Run | M6: FAILED
A7: TC-SEL-006 | B7: Name | C7: Name length at the limits | D7: Boundary Value Analysis | E7: Medium | F7: The seller registration page is open. The email, mobile number and other unique values in the test data are not yet registered. | G7: 1. Fill in all other fields with valid data. 2. Enter each first name in the test data, one per attempt. 3. Click Register. | H7: 1 character: M (reject) 2 characters: Mo (accept) 50 characters: Maria Cristina Angelica Bernadette Josefina Leonor (accept) 51 characters: Maria Cristina Angelica Bernadette Josefina Leonora (reject) | I7: 1 and 51 characters are rejected with a length message. 2 and 50 characters are accepted. | J7: A2 | K7: A 1-letter name was rejected as too short. 2 letters and 50 characters were both fine. The field doesn't let you type past 50 characters, and when I forced 51 through it was rejected as too long. | L7: Run | M7: PASSED
A8: TC-SEL-007 | B8: Email | C8: Email in an invalid format | D8: Equivalence Partitioning | E8: High | F8: The seller registration page is open. | G8: 1. Fill in all other fields with valid data. 2. Enter each email in the test data, one per attempt. 3. Click Register. | H8: mariaclara.santosexample.com (no @) mariaclara.santos@ (no domain) @example.com (no name) mariaclara.santos@example (no .com) mariaclara santos@example.com (space) | I8: Each value is rejected with a message asking for a valid email address. No account is created. | J8: A3 | K8: Most of the bad emails were stopped right away with a message to enter a valid email. But mariaclara.santos@example (no .com) went through. It created the account and sent me to the email verification page. | L8: Run | M8: FAILED
A9: TC-SEL-008 | B9: Email | C9: Email that is already registered | D9: Equivalence Partitioning | E9: High | F9: The seller registration page is open. The seller account mariaclara.santos@example.com already exists. | G9: 1. Fill in all other fields with valid data. 2. Enter the existing email. 3. Click Register. | H9: Email: mariaclara.santos@example.com | I9: Registration is blocked. A message says the email is already in use. No account is created. | J9: A3 | K9: It stopped me and said the email address is already registered. No second account was made. | L9: Run | M9: PASSED
A10: TC-SEL-009 | B10: Email | C10: Registered email typed in capital letters | D10: Error Guessing | E10: Medium | F10: The seller registration page is open. The seller account mariaclara.santos@example.com already exists. | G10: 1. Fill in all other fields with valid data. 2. Enter the same email in capital letters. 3. Click Register. | H10: Email: MARIACLARA.SANTOS@EXAMPLE.COM | I10: The email is treated as a duplicate. Registration is blocked. | J10: A3 | K10: Same email in all capitals was still caught as already registered. | L10: Run | M10: PASSED
A11: TC-SEL-010 | B11: Email | C11: Email with spaces before and after | D11: Error Guessing | E11: Low | F11: The seller registration page is open. The email, mobile number and other unique values in the test data are not yet registered. | G11: 1. Fill in all other fields with valid data. 2. Type two spaces before and after the email. 3. Click Register. | H11: Email: " seller.test01@example.com " | I11: The spaces are removed and the email is saved as seller.test01@example.com. | J11: A3 | K11: The extra spaces were removed. The verification page showed the email without them. | L11: Run | M11: PASSED
A12: TC-SEL-011 | B12: Mobile Number | C12: Mobile number in an invalid format | D12: Equivalence Partitioning | E12: High | F12: The seller registration page is open. | G12: 1. Fill in all other fields with valid data. 2. Enter each mobile number in the test data, one per attempt. 3. Click Register. | H12: 0917ABC4567 (letters) 0917-123-456 (symbols, too short) 12345678901 (does not start with 09) 02-8123-4567 (landline) | I12: Each value is rejected with a message asking for a valid mobile number. | J12: A4 | K12: Letters, dashes and the landline number were all rejected with an invalid format message. But when I typed 12345678901, the page quietly changed it to 09345678901 and accepted it without any warning. | L12: Run | M12: FAILED
... A45: TC-SEL-044 | B45: Access Control | C45: Open another role's pages | D45: Error Guessing | E45: Medium | F45: The Approved seller account mariaclara.santos@example.com is logged in. | G45: 1. Paste the address of each dashboard in the test data into the browser, one at a time. | H45: Admin dashboard Logistics dashboard Rider dashboard | I45: Access is denied each time (error 403 or redirect). No data from the other role is shown. | J45: A16 | K45: Logged in as the seller, the admin, logistics and rider dashboards all showed a 403 Unauthorized message. | L45: Run | M45: PASSED

Sheet Logistics
A1: Test Case ID | B1: Module | C1: Test Scenario | D1: Technique | E1: Priority | F1: Preconditions | G1: Test Steps | H1: Test Data | I1: Expected Result | J1: Assumption Ref | K1: Actual Result | L1: Status | M1: Remarks
A2: TC-LOG-001 | B2: Registration Form | C2: Register with all valid data | D2: Use Case Testing | E2: High | F2: The logistics registration page is open. The email, mobile number and other unique values in the test data are not yet registered. | G2: 1. Fill in every field with the test data. 2. Click Register. | H2: Company Name: Bilis Hatid Express Inc. SEC Registration No.: CS202012345 TIN: 234-567-890-000 Region: National Capital Region (NCR) Province: Metro Manila City / Municipality: Pasig City Barangay: Kapitolyo Street Address: Unit 5B, 88 West Capitol Drive Postal Code: 1603 Contact Person First Name: Carlos Antonio Contact Person Last Name: Mendoza Position: Operations Manager Email: operations@bilishatid.example.com Mobile Number: 09285551234 Service Areas: NCR; Region IV-A (CALABARZON) SEC Certificate (upload): sec_certificate.pdf (1.0 MB) BIR Form 2303 (upload): bir_2303.pdf (1.1 MB) Mayor's / Business Permit (upload): mayors_permit.pdf (1.3 MB) Valid ID of Authorized Representative (upload): govt_id_front.jpg (1.2 MB) Password: Hatid@2026 Confirm Password: Hatid@2026 Terms and Privacy Policy: Ticked | I2: The form is accepted with no validation errors. A success message is shown, a 6-digit OTP is sent to the email, and the email verification page opens. The account is saved with status Unverified. | J2: A1, A9, A12 | K2: The 6 digit send OTP to email. But the form will fill up right after registration. It has no validation error also | L2: Run | M2: PASSED
A3: TC-LOG-002 | B3: Required Fields | C3: Submit a completely empty form | D3: Equivalence Partitioning | E3: High | F3: The logistics registration page is open. | G3: 1. Leave every field blank and every dropdown on its default option. 2. Click Register. | H3: All fields blank | I3: Registration is blocked. A required-field message is shown for every mandatory field. No account is created and no OTP is sent. | J3: A1 | K3: Registration is not blocked. Account still created but not verified until the requirements is fulfill in the profile | L3: Run | M3: FAILED
A4: TC-LOG-003 | B4: Required Fields | C4: Leave one required field blank at a time | D4: Equivalence Partitioning | E4: High | F4: The logistics registration page is open. | G4: 1. Fill in all fields with valid data. 2. Clear one required field. 3. Click Register. 4. Repeat for each field in the test data. | H4: Clear in turn: Company Name SEC Registration No. TIN Region Province City / Municipality Barangay Street Address Postal Code Contact Person First Name Contact Person Last Name Position Email Mobile Number Service Areas SEC Certificate (upload) BIR Form 2303 (upload) Mayor's / Business Permit (upload) Valid ID of Authorized Representative (upload) Password Confirm Password | I4: Each time, registration is blocked and a required-field message is shown on the blank field only. Other entered values (except passwords and uploads) are kept. No account is created. | J4: A1 | K4: registration is not blocked but a required - field message shown on the blank field only. Account is not created | L4: Run | M4: FAILED
A5: TC-LOG-004 | B5: Name | C5: Name with numbers or symbols | D5: Equivalence Partitioning | E5: Medium | F5: The logistics registration page is open. | G5: 1. Fill in all other fields with valid data. 2. Enter the test data in the name fields. 3. Click Register. | H5: First Name: Carlos Antonio7 Last Name: Dela Cruz@# | I5: Registration is blocked. A message on each name field says only letters are allowed. | J5: A2 | K5: Numbers or special character is blocked. Letters is only allowed | L5: Run | M5: PASSED
A6: TC-LOG-005 | B6: Name | C6: Name with ñ and allowed punctuation | D6: Equivalence Partitioning | E6: Low | F6: The logistics registration page is open. The email, mobile number and other unique values in the test data are not yet registered. | G6: 1. Fill in all other fields with valid data. 2. Enter the test data in the name fields. 3. Click Register. | H6: First Name: Iñigo Rafael Last Name: Muñoz-D'Angelo | I6: The names are accepted and saved exactly as typed, including ñ. | J6: A2 | K6: ñ is not accepted | L6: Run | M6: FAILED
A7: TC-LOG-006 | B7: Name | C7: Name length at the limits | D7: Boundary Value Analysis | E7: Medium | F7: The logistics registration page is open. The email, mobile number and other unique values in the test data are not yet registered. | G7: 1. Fill in all other fields with valid data. 2. Enter each first name in the test data, one per attempt. 3. Click Register. | H7: 1 character: C (reject) 2 characters: Co (accept) 50 characters: Maria Cristina Angelica Bernadette Josefina Leonor (accept) 51 characters: Maria Cristina Angelica Bernadette Josefina Leonora (reject) | I7: 1 and 51 characters are rejected with a length message. 2 and 50 characters are accepted. | J7: A2 | K7: 2 and 50 characters are accepted | L7: Run | M7: PASSED
A8: TC-LOG-007 | B8: Email | C8: Email in an invalid format | D8: Equivalence Partitioning | E8: High | F8: The logistics registration page is open. | G8: 1. Fill in all other fields with valid data. 2. Enter each email in the test data, one per attempt. 3. Click Register. | H8: operations.bilishatidexample.com (no @) operations.bilishatid@ (no domain) @example.com (no name) operations.bilishatid@example (no .com) operations bilishatid@example.com (space) | I8: Each value is rejected with a message asking for a valid email address. No account is created. | J8: A3 | K8: Asking for a valid email address. | L8: Run | M8: PASSED
A9: TC-LOG-008 | B9: Email | C9: Email that is already registered | D9: Equivalence Partitioning | E9: High | F9: The logistics registration page is open. The logistics account operations@bilishatid.example.com (Bilis Hatid Express Inc.) already exists. | G9: 1. Fill in all other fields with valid data. 2. Enter the existing email. 3. Click Register. | H9: Email: operations@bilishatid.example.com | I9: Registration is blocked. A message says the email is already in use. No account is created. | J9: A3 | K9: Registration is blocked when the email is already in used | L9: Run | M9: PASSED
A10: TC-LOG-009 | B10: Email | C10: Registered email typed in capital letters | D10: Error Guessing | E10: Medium | F10: The logistics registration page is open. The logistics account operations@bilishatid.example.com (Bilis Hatid Express Inc.) already exists. | G10: 1. Fill in all other fields with valid data. 2. Enter the same email in capital letters. 3. Click Register. | H10: Email: OPERATIONS@BILISHATID.EXAMPLE.COM | I10: The email is treated as a duplicate. Registration is blocked. | J10: A3 | K10: The email is treated as a duplicate. Registration is blocked. | L10: Not Run | M10: PASSED
A11: TC-LOG-010 | B11: Email | C11: Email with spaces before and after | D11: Error Guessing | E11: Low | F11: The logistics registration page is open. The email, mobile number and other unique values in the test data are not yet registered. | G11: 1. Fill in all other fields with valid data. 2. Type two spaces before and after the email. 3. Click Register. | H11: Email: " logistics.test01@example.com " | I11: The spaces are removed and the email is saved as logistics.test01@example.com. | J11: A3 | K11: the spaces are not removed | L11: Not Run | M11: PASSED
A12: TC-LOG-011 | B12: Mobile Number | C12: Mobile number in an invalid format | D12: Equivalence Partitioning | E12: High | F12: The logistics registration page is open. | G12: 1. Fill in all other fields with valid data. 2. Enter each mobile number in the test data, one per attempt. 3. Click Register. | H12: 0917ABC4567 (letters) 0917-123-456 (symbols, too short) 12345678901 (does not start with 09) 02-8123-4567 (landline) | I12: Each value is rejected with a message asking for a valid mobile number. | J12: A4 | K12: The other characters is blocked execpt numbers. | L12: Run | M12: PASSED
... A45: TC-LOG-044 | B45: Access Control | C45: Open another role's pages | D45: Error Guessing | E45: Medium | F45: The Approved logistics account operations@bilishatid.example.com is logged in. | G45: 1. Paste the address of each dashboard in the test data into the browser, one at a time. | H45: Admin dashboard Seller dashboard Rider dashboard | I45: Access is denied each time (error 403 or redirect). No data from the other role is shown. | J45: A16 | K45: Access is denied each time (error 403 or redirect). No data from the other role is shown. | L45: Run | M45: PASSED

Sheet Rider
A1: Test Case ID | B1: Module | C1: Test Scenario | D1: Technique | E1: Priority | F1: Preconditions | G1: Test Steps | H1: Test Data | I1: Expected Result | J1: Assumption Ref | K1: Actual Result | L1: Status | M1: Remarks
A2: TC-RID-001 | B2: Add Rider Form | C2: Create a rider with all valid data | D2: Use Case Testing | E2: High | F2: The Approved logistics account operations@bilishatid.example.com is logged in and the Add Rider form is open. The email, mobile number, license number and plate number in the test data are not yet registered. | G2: 1. Fill in every field with the test data. 2. Click Save. | H2: First Name: Pedro Jose Last Name: Garcia Date of Birth: 03/22/1995 Email: pedrojose.garcia@example.com Mobile Number: 09451239876 Driver's License No.: N01-23-456789 License Expiry Date: 03/22/2030 Vehicle Type: Motorcycle Plate Number: 123ABC Driver's License (upload): drivers_license.jpg (1.5 MB) Vehicle OR/CR (upload): or_cr.pdf (900 KB) | I2: The rider is saved with no validation errors and appears in the rider list of Bilis Hatid Express Inc. with status Pending Activation. An activation email is sent to pedrojose.garcia@example.com. | J2: A1, A13 | L2: Not Run
A3: TC-RID-002 | B3: Required Fields | C3: Submit a completely empty form | D3: Equivalence Partitioning | E3: High | F3: The Approved logistics account operations@bilishatid.example.com is logged in and the Add Rider form is open. | G3: 1. Leave every field blank and every dropdown on its default option. 2. Click Save. | H3: All fields blank | I3: Saving is blocked. A required-field message is shown for every mandatory field. No rider is created and no email is sent. | J3: A1 | L3: Not Run
A4: TC-RID-003 | B4: Required Fields | C4: Leave one required field blank at a time | D4: Equivalence Partitioning | E4: High | F4: The Approved logistics account operations@bilishatid.example.com is logged in and the Add Rider form is open. | G4: 1. Fill in all fields with valid data. 2. Clear one required field. 3. Click Save. 4. Repeat for each field in the test data. | H4: Clear in turn: First Name Last Name Date of Birth Email Mobile Number Driver's License No. License Expiry Date Vehicle Type Plate Number Driver's License (upload) Vehicle OR/CR (upload) | I4: Each time, saving is blocked and a required-field message is shown on the blank field only. Other entered values (except uploads) are kept. No rider is created. | J4: A1 | L4: Not Run
A5: TC-RID-004 | B5: Name | C5: Name with numbers or symbols | D5: Equivalence Partitioning | E5: Medium | F5: The Approved logistics account operations@bilishatid.example.com is logged in and the Add Rider form is open. | G5: 1. Fill in all other fields with valid data. 2. Enter the test data in the name fields. 3. Click Save. | H5: First Name: Pedro Jose99 Last Name: Dela Cruz@# | I5: Saving is blocked. A message on each name field says only letters are allowed. | J5: A2 | L5: Not Run
A6: TC-RID-005 | B6: Name | C6: Name length at the limits | D6: Boundary Value Analysis | E6: Medium | F6: The Approved logistics account operations@bilishatid.example.com is logged in and the Add Rider form is open. The email, mobile number, license number and plate number in the test data are not yet registered. | G6: 1. Fill in all other fields with valid data. 2. Enter each first name in the test data, one per attempt. 3. Click Save. | H6: 1 character: P (reject) 2 characters: Po (accept) 50 characters: Maria Cristina Angelica Bernadette Josefina Leonor (accept) 51 characters: Maria Cristina Angelica Bernadette Josefina Leonora (reject) | I6: 1 and 51 characters are rejected with a length message. 2 and 50 characters are accepted. | J6: A2 | L6: Not Run
A7: TC-RID-006 | B7: Date of Birth | C7: Age at the 18-year limit | D7: Boundary Value Analysis | E7: High | F7: The Approved logistics account operations@bilishatid.example.com is logged in and the Add Rider form is open. The email, mobile number, license number and plate number in the test data are not yet registered. | G7: 1. Fill in all other fields with valid data. 2. Enter each date of birth in the test data, one per attempt. 3. Click Save. | H7: ="Born "&TEXT(EDATE(TODAY(),-216)+1,"mm/dd/yyyy")&" (17 years old, reject)"&CHAR(10)&"Born "&TEXT(EDATE(TODAY(),-216),"mm/dd/yyyy")&" (turns 18 today, accept)"&CHAR(10)&"Born "&TEXT(EDATE(TODAY(),-216)-1,"mm/dd/yyyy")&" (18 years and 1 day, accept)" -> Born 10/15/2008 (17 years old, reject) Born 10/14/2008 (turns 18 today, accept) Born 10/13/2008 (18 years and 1 day, accept) | I7: The 17-year-old date is rejected with a message that the person must be at least 18. The other two dates are accepted. | J7: A6 | L7: Not Run
A8: TC-RID-007 | B8: Email | C8: Email in an invalid format | D8: Equivalence Partitioning | E8: High | F8: The Approved logistics account operations@bilishatid.example.com is logged in and the Add Rider form is open. | G8: 1. Fill in all other fields with valid data. 2. Enter each email in the test data, one per attempt. 3. Click Save. | H8: pedrojose.garciaexample.com (no @) pedrojose.garcia@ (no domain) @example.com (no name) pedrojose.garcia@example (no .com) pedrojose garcia@example.com (space) | I8: Each value is rejected with a message asking for a valid email address. No rider is created. | J8: A3 | L8: Not Run
A9: TC-RID-008 | B9: Email | C9: Email already used by an account of another role | D9: Equivalence Partitioning | E9: High | F9: The Approved logistics account operations@bilishatid.example.com is logged in and the Add Rider form is open. The buyer account juanmiguel.delacruz@example.com already exists. | G9: 1. Fill in all other fields with valid data. 2. Enter the existing email. 3. Click Save. | H9: Email: juanmiguel.delacruz@example.com | I9: Saving is blocked. A message says the email is already in use. No rider is created. | J9: A3 | L9: Not Run
A10: TC-RID-009 | B10: Mobile Number | C10: Mobile number in an invalid format | D10: Equivalence Partitioning | E10: High | F10: The Approved logistics account operations@bilishatid.example.com is logged in and the Add Rider form is open. | G10: 1. Fill in all other fields with valid data. 2. Enter each mobile number in the test data, one per attempt. 3. Click Save. | H10: 0917ABC4567 (letters) 0917-123-456 (symbols, too short) 12345678901 (does not start with 09) 02-8123-4567 (landline) | I10: Each value is rejected with a message asking for a valid mobile number. | J10: A4 | L10: Not Run
A11: TC-RID-010 | B11: Mobile Number | C11: Mobile number length at the limits | D11: Boundary Value Analysis | E11: High | F11: The Approved logistics account operations@bilishatid.example.com is logged in and the Add Rider form is open. The email, mobile number, license number and plate number in the test data are not yet registered. | G11: 1. Fill in all other fields with valid data. 2. Enter each mobile number in the test data, one per attempt. 3. Click Save. | H11: 10 digits: 0917123456 (reject) 11 digits: 09170000001 (accept) 12 digits: 091712345678 (reject) | I11: 10 and 12 digits are rejected with a length message. 11 digits is accepted. | J11: A4 | L11: Not Run
A12: TC-RID-011 | B12: Mobile Number | C12: Mobile number that is already registered | D12: Equivalence Partitioning | E12: Medium | F12: The Approved logistics account operations@bilishatid.example.com is logged in and the Add Rider form is open. An account already exists with mobile number 09171234567. | G12: 1. Fill in all other fields with valid data. 2. Enter the existing mobile number. 3. Click Save. | H12: Mobile: 09171234567 | I12: Saving is blocked. A message says the mobile number is already in use. | J12: A4 | L12: Not Run
A13: TC-RID-012 | B13: License and Vehicle | C13: Driver's license number in an invalid format | D13: Equivalence Partitioning | E13: High | F13: The Approved logistics account operations@bilishatid.example.com is logged in and the Add Rider form is open. | G13: 1. Fill in all other fields with valid data. 2. Enter each license number in the test data, one per attempt. 3. Click Save. | H13: N01-23-45678 (one digit short) N01-23-4567890 (one digit extra) 101-23-456789 (no letter) N0123456789X (letter at the end) | I13: Each value is rejected with a message showing the format A00-00-000000. | J13: A15 | L13: Not Run
A14: TC-RID-013 | B14: License and Vehicle | C14: Driver's license number already registered | D14: Equivalence Partitioning | E14: High | F14: The Approved logistics account operations@bilishatid.example.com is logged in and the Add Rider form is open. The rider pedrojose.garcia@example.com already exists. | G14: 1. Fill in all other fields with valid data. 2. Enter the existing license number. 3. Click Save. | H14: Driver's License No.: N01-23-456789 | I14: Saving is blocked. A message says the license number is already registered. | J14: A14 | L14: Not Run
A15: TC-RID-014 | B15: License and Vehicle | C15: License expiry date at the limit | D15: Boundary Value Analysis | E15: High | F15: The Approved logistics account operations@bilishatid.example.com is logged in and the Add Rider form is open. The email, mobile number, license number and plate number in the test data are not yet registered. | G15: 1. Fill in all other fields with valid data. 2. Enter each expiry date in the test data, one per attempt. 3. Click Save. | H15: ="Expiry "&TEXT(TODAY()-1,"mm/dd/yyyy")&" (yesterday, reject)"&CHAR(10)&"Expiry "&TEXT(TODAY(),"mm/dd/yyyy")&" (today, accept)"&CHAR(10)&"Expiry "&TEXT(TODAY()+1,"mm/dd/yyyy")&" (tomorrow, accept)" -> Expiry 10/13/2026 (yesterday, reject) Expiry 10/14/2026 (today, accept) Expiry 10/15/2026 (tomorrow, accept) | I15: Yesterday's date is rejected with a message that the license is expired. Today's and tomorrow's dates are accepted. | J15: A15 | L15: Not Run
A16: TC-RID-015 | B16: License and Vehicle | C16: Plate number already registered | D16: Equivalence Partitioning | E16: Medium | F16: The Approved logistics account operations@bilishatid.example.com is logged in and the Add Rider form is open. The rider pedrojose.garcia@example.com already exists. | G16: 1. Fill in all other fields with valid data. 2. Enter the existing plate number. 3. Click Save. | H16: Plate Number: 123ABC | I16: Saving is blocked. A message says the plate number is already registered. | J16: A14 | L16: Not Run
A17: TC-RID-016 | B17: Document Upload | C17: Upload documents in each accepted file type | D17: Equivalence Partitioning | E17: High | F17: The Approved logistics account operations@bilishatid.example.com is logged in and the Add Rider form is open. The email, mobile number, license number and plate number in the test data are not yet registered. | G17: 1. Fill in all other fields with valid data. 2. Upload the files in the test data. 3. Click Save. | H17: Driver's License: drivers_license.jpg (1.5 MB), then drivers_license.png (2.0 MB), then drivers_license.pdf (700 KB) Vehicle OR/CR: or_cr.pdf (900 KB) | I17: Each file is accepted and its name or preview is shown. The rider is saved. | J17: A10 | L17: Not Run
A18: TC-RID-017 | B18: Document Upload | C18: Upload a file type that is not accepted | D18: Equivalence Partitioning | E18: High | F18: The Approved logistics account operations@bilishatid.example.com is logged in and the Add Rider form is open. | G18: 1. Fill in all other fields with valid data. 2. Try to upload each file in the test data to Driver's License, one per attempt. 3. Click Save. | H18: price_list.docx (320 KB) store_banner.gif (480 KB) installer.exe (2.1 MB) | I18: Each file is rejected with a message listing the accepted types (JPG, PNG, PDF). No rider is created. | J18: A10 | L18: Not Run
A19: TC-RID-018 | B19: Document Upload | C19: File size at the limit | D19: Boundary Value Analysis | E19: High | F19: The Approved logistics account operations@bilishatid.example.com is logged in and the Add Rider form is open. The email, mobile number, license number and plate number in the test data are not yet registered. | G19: 1. Fill in all other fields with valid data. 2. Upload each file in the test data to Driver's License, one per attempt. 3. Click Save. | H19: size_4.9MB.jpg (accept) size_5.0MB.jpg, exactly 5,120 KB (accept) size_5.1MB.jpg (reject) | I19: The 4.9 MB and 5.0 MB files are accepted. The 5.1 MB file is rejected with a maximum-size message. | J19: A10 | L19: Not Run
A20: TC-RID-019 | B20: Add Rider Form | C20: Click Save several times quickly | D20: Error Guessing | E20: Medium | F20: The Approved logistics account operations@bilishatid.example.com is logged in and the Add Rider form is open. The email, mobile number, license number and plate number in the test data are not yet registered. | G20: 1. Fill in all fields with the Account 2 data from the Test Data sheet. 2. Click Save three times in quick succession. | H20: Account 2 data (Test Data sheet, column G) | I20: Only one rider is created and only one activation email is sent. | J20: A3 | L20: Not Run
A21: TC-RID-020 | B21: Account Activation | C21: Rider activates the account with a valid password | D21: State Transition | E21: High | F21: The rider pedrojose.garcia@example.com has status Pending Activation and the activation email has been read from the mail catcher. | G21: 1. Open the activation link from the email within 24 hours. 2. Enter and confirm the password. 3. Click Activate. | H21: Password: Rider@2026 Confirm Password: Rider@2026 | I21: The password is saved. The rider's status changes from Pending Activation to Active, and the login page opens with a success message. | J21: A5, A13 | L21: Not Run
A22: TC-RID-021 | B22: Account Activation | C22: Set a password that breaks the password rule | D22: Decision Table | E22: High | F22: The rider pedrojose.garcia@example.com has status Pending Activation and the activation email has been read from the mail catcher. | G22: 1. Open the activation link. 2. Enter each password in both fields, one per attempt. 3. Click Activate. | H22: 7 characters: Ride@26 No uppercase: rider@2026 No lowercase: RIDER@2026 No number: Rider@abcd No special character: Rider2026 | I22: Each password is rejected with a message stating the password rule. The rider stays Pending Activation. | J22: A5 | L22: Not Run
